Workbook

Sheet 使い方
A1: 【このファイルについて】
A2: アップロード動作確認用のダミーデータです。試作シートを8件収録しています。
A3: 現在のアプリは配合表（原料・配合量）は読み込まないため、このファイルには含めていません。

Sheet コード表
A1: カテゴリーコード表 | D1: 作成者コード表
A2: コード | B2: 名称 | D2: コード | E2: 氏名
A3: RK | B3: 冷菓 | D3: tnk | E3: 田中
A4: CH | B4: チョコレート | D4: myt | E4: 宮田

Sheet 表紙
A1: 試作ブック情報（表紙）
A3: ブックID | B3: BOOK-2026-0002 | C3: ブック名 | D3: バニラアイス フレーバー展開検討（山田担当分）
A4: 企画ID | B4: PJ-2026-021 | C4: カテゴリーコード | D4: RK
A5: 作成者 | B5: 山田 太郎 | C5: 作成者コード | D5: tnk
A6: 作成日 | B6: 2026-07-01 | C6: 作成時刻 | D6: 09:00

Sheet 試作シート1
A1: 配合ID | B1: =試作一覧!C2 -> RK_tnk_202607021000_1
A2: タイトル | B2: バニラベース 甘味料検討
A3: ステータス | B3: 最終確定
A4: 作成者 | B4: 山田 太郎 | C4: 作成者コード | D4: tnk
A5: 作成日 | B5: 2026-07-02 | C5: 作成時刻 | D5: 10:00
A6: 更新日 | B6: 2026-07-05 | C6: 更新時刻 | D6: 14:00
A7: 完了日 | B7: 2026-07-05
A8: 背景・目的 | B8: コストダウンのため砂糖の一部を代替甘味料に置き換えたい。
A9: 結論 | B9: 羅漢果エキス20%置換で官能評価に有意差なし。採用候補。
A10: 次のアクション
A12: ■ 配合表（配合比較）
A13: 配合No | C13: a | E13: b | G13: c | I13: d | K13: e | M13: f | O13: g | Q13: h | S13: i | U13: j | W13: k | Y13: l
A14: 配合タイトル | C14: 北海道クリームベース | E14: 豆乳ベース | G14: 低糖質（羅漢果20%置換）
A15: 配合目的・意図 | C15: 従来品の対照区 | E15: 乳成分低減の検討 | G15: コストダウン検討
A16: 配合結果 | C16: 甘味・コクとも良好 | E16: コクがやや弱い | G16: 甘味の質は近い、後味わずかに残る
A17: 試作評価 | C17: ◎ | E17: △ | G17: ○

Sheet 試作シート2
A1: 配合ID | B1: =試作一覧!C3 -> RK_tnk_202607180915_2
A2: タイトル | B2: コーティングチョコ 口どけ改善
A3: ステータス | B3: 作成中
A4: 作成者 | B4: 山田 太郎 | C4: 作成者コード | D4: tnk
A5: 作成日 | B5: 2026-07-18 | C5: 作成時刻 | D5: 09:15
A6: 更新日 | B6: 2026-07-20 | C6: 更新時刻 | D6: 10:00
A7: 完了日
A8: 背景・目的 | B8: 夏季における口どけの重さを改善したい。
A9: 結論
A10: 次のアクション
A12: ■ 配合表（配合比較）
A13: 配合No | C13: a | E13: b | G13: c | I13: d | K13: e | M13: f | O13: g | Q13: h | S13: i | U13: j | W13: k | Y13: l
A14: 配合タイトル | C14: カカオ55%配合 | E14: カカオ65%配合
A15: 配合目的・意図 | C15: 現行品 | E15: 口どけ改善狙い
A16: 配合結果 | C16: 対照区 | E16: 口どけ改善、香り強すぎとの声も
A17: 試作評価 | C17: ○ | E17: ○

Sheet 試作シート3
A1: 配合ID | B1: =試作一覧!C4 -> RK_tnk_202608101000_3
A2: タイトル | B2: オーバーラン（空気含有率）検討
A3: ステータス | B3: 作成中
A4: 作成者 | B4: 山田 太郎 | C4: 作成者コード | D4: tnk
A5: 作成日 | B5: 2026-08-10 | C5: 作成時刻 | D5: 10:00
A6: 更新日 | B6: 2026-08-14 | C6: 更新時刻 | D6: 11:00
A7: 完了日
A8: 背景・目的 | B8: 口当たりの軽さと形状保持のバランスを検証したい。
A9: 結論
A10: 次のアクション
A12: ■ 配合表（配合比較）
A13: 配合No | C13: a | E13: b | G13: c | I13: d | K13: e | M13: f | O13: g | Q13: h | S13: i | U13: j | W13: k | Y13: l
A14: 配合タイトル | C14: オーバーラン80% | E14: オーバーラン60% | G14: オーバーラン100% | I14: オーバーラン90% | K14: オーバーラン70% | M14: オーバーラン90%+安定剤増
A15: 配合目的・意図 | C15: 現行品相当 | E15: 重めの口当たり | G15: 軽い口当たり | I15: 中間配合 | K15: やや重めの中間 | M15: 形状保持強化
A16: 配合結果 | C16: 対照区 | E16: コク増だが重い | G16: 軽すぎて安っぽい印象 | I16: バランス良好 | K16: 許容範囲 | M16: 型崩れ改善、再評価要
A17: 試作評価 | C17: ○ | E17: △ | G17: △ | I17: ○ | K17: ○ | M17: ○

Sheet 試作シート4
A1: 配合ID | B1: =試作一覧!C5 -> RK_tnk_202608251400_4
A2: タイトル | B2: 保存性向上（安定剤比較）
A3: ステータス | B3: 最終確定
A4: 作成者 | B4: 山田 太郎 | C4: 作成者コード | D4: tnk
A5: 作成日 | B5: 2026-08-25 | C5: 作成時刻 | D5: 14:00
A6: 更新日 | B6: 2026-09-01 | C6: 更新時刻 | D6: 15:00
A7: 完了日 | B7: 2026-09-01
A8: 背景・目的 | B8: 流通期間延長のため氷結晶成長の抑制を狙う。
A9: 結論 | B9: 安定剤B 0.2%配合で氷結晶の粗大化を抑制、採用決定。
A10: 次のアクション
A12: ■ 配合表（配合比較）
A13: 配合No | C13: a | E13: b | G13: c | I13: d | K13: e | M13: f | O13: g | Q13: h | S13: i | U13: j | W13: k | Y13: l
A14: 配合タイトル | C14: 安定剤A 0.1% | E14: 安定剤A 0.2% | G14: 安定剤B 0.2% | I14: 安定剤B 0.3%
A15: 配合目的・意図 | C15: 現行品 | E15: 増量検討 | G15: 種類変更検討 | I15: さらに増量
A16: 配合結果 | C16: 対照区 | E16: 食感やや重い | G16: 食感良好、保存性向上 | I16: ガム感が出る
A17: 試作評価 | C17: ○ | E17: △ | G17: ◎ | I17: △

Sheet 試作一覧
A1: 試作No | B1: シート名 | C1: 配合ID | D1: タイトル | E1: ステータス | F1: 作成者 | G1: 作成者コード | H1: 作成日 | I1: 作成時刻 | J1: 更新日 | K1: 更新時刻 | L1: 完了日 | M1: 背景・目的 | N1: 結論
A2: =ROW()-1 -> 1 | B2: =IF(ISERROR(試作シート1!$A$1),"",HYPERLINK("#'試作シート1'!A1","試作シート1")) -> 試作シート1 | C2: =IF(ISERROR(試作シート1!$A$1),"",IF(OR(表紙!$D$4="",試作シート1!$D$4="",試作シート1!$B$5="",試作シート1!$D$5=""),"(入力待ち)",表紙!$D$4&"_"&試作シート1!$D$4&"_"&TEXT(試作シート1!$B$5,"yyyymmdd")&TEXT(試作シート1!$D$5,"hhmm")&"_"&A2)) -> RK_tnk_202607021000_1 | D2: =IFERROR(IF(試作シート1!B2="","",試作シート1!B2),"") -> バニラベース 甘味料検討 | E2: =IFERROR(IF(試作シート1!B3="","",試作シート1!B3),"") -> 最終確定 | F2: =IFERROR(IF(試作シート1!B4="","",試作シート1!B4),"") -> 山田 太郎 | G2: =IFERROR(IF(試作シート1!D4="","",試作シート1!D4),"") -> tnk | H2: =IFERROR(IF(試作シート1!B5="","",試作シート1!B5),"") -> 2026-07-02 | I2: =IFERROR(IF(試作シート1!D5="","",試作シート1!D5),"") -> 10:00 | J2: =IFERROR(IF(試作シート1!B6="","",試作シート1!B6),"") -> 2026-07-05 | K2: =IFERROR(IF(試作シート1!D6="","",試作シート1!D6),"") -> 14:00 | L2: =IFERROR(IF(試作シート1!B7="","",試作シート1!B7),"") -> 2026-07-05 | M2: =IFERROR(IF(試作シート1!B8="","",試作シート1!B8),"") -> コストダウンのため砂糖の一部を代替甘味料に置き換えたい。 | N2: =IFERROR(IF(試作シート1!B9="","",試作シート1!B9),"") -> 羅漢果エキス20%置換で官能評価に有意差なし。採用候補。
A3: =ROW()-1 -> 2 | B3: =IF(ISERROR(試作シート2!$A$1),"",HYPERLINK("#'試作シート2'!A1","試作シート2")) -> 試作シート2 | C3: =IF(ISERROR(試作シート2!$A$1),"",IF(OR(表紙!$D$4="",試作シート2!$D$4="",試作シート2!$B$5="",試作シート2!$D$5=""),"(入力待ち)",表紙!$D$4&"_"&試作シート2!$D$4&"_"&TEXT(試作シート2!$B$5,"yyyymmdd")&TEXT(試作シート2!$D$5,"hhmm")&"_"&A3)) -> RK_tnk_202607180915_2 | D3: =IFERROR(IF(試作シート2!B2="","",試作シート2!B2),"") -> コーティングチョコ 口どけ改善 | E3: =IFERROR(IF(試作シート2!B3="","",試作シート2!B3),"") -> 作成中 | F3: =IFERROR(IF(試作シート2!B4="","",試作シート2!B4),"") -> 山田 太郎 | G3: =IFERROR(IF(試作シート2!D4="","",試作シート2!D4),"") -> tnk | H3: =IFERROR(IF(試作シート2!B5="","",試作シート2!B5),"") -> 2026-07-18 | I3: =IFERROR(IF(試作シート2!D5="","",試作シート2!D5),"") -> 09:15 | J3: =IFERROR(IF(試作シート2!B6="","",試作シート2!B6),"") -> 2026-07-20 | K3: =IFERROR(IF(試作シート2!D6="","",試作シート2!D6),"") -> 10:00 | L3: =IFERROR(IF(試作シート2!B7="","",試作シート2!B7),"") | M3: =IFERROR(IF(試作シート2!B8="","",試作シート2!B8),"") -> 夏季における口どけの重さを改善したい。 | N3: =IFERROR(IF(試作シート2!B9="","",試作シート2!B9),"")
A4: =ROW()-1 -> 3 | B4: =IF(ISERROR(試作シート3!$A$1),"",HYPERLINK("#'試作シート3'!A1","試作シート3")) -> 試作シート3 | C4: =IF(ISERROR(試作シート3!$A$1),"",IF(OR(表紙!$D$4="",試作シート3!$D$4="",試作シート3!$B$5="",試作シート3!$D$5=""),"(入力待ち)",表紙!$D$4&"_"&試作シート3!$D$4&"_"&TEXT(試作シート3!$B$5,"yyyymmdd")&TEXT(試作シート3!$D$5,"hhmm")&"_"&A4)) -> RK_tnk_202608101000_3 | D4: =IFERROR(IF(試作シート3!B2="","",試作シート3!B2),"") -> オーバーラン（空気含有率）検討 | E4: =IFERROR(IF(試作シート3!B3="","",試作シート3!B3),"") -> 作成中 | F4: =IFERROR(IF(試作シート3!B4="","",試作シート3!B4),"") -> 山田 太郎 | G4: =IFERROR(IF(試作シート3!D4="","",試作シート3!D4),"") -> tnk | H4: =IFERROR(IF(試作シート3!B5="","",試作シート3!B5),"") -> 2026-08-10 | I4: =IFERROR(IF(試作シート3!D5="","",試作シート3!D5),"") -> 10:00 | J4: =IFERROR(IF(試作シート3!B6="","",試作シート3!B6),"") -> 2026-08-14 | K4: =IFERROR(IF(試作シート3!D6="","",試作シート3!D6),"") -> 11:00 | L4: =IFERROR(IF(試作シート3!B7="","",試作シート3!B7),"") | M4: =IFERROR(IF(試作シート3!B8="","",試作シート3!B8),"") -> 口当たりの軽さと形状保持のバランスを検証したい。 | N4: =IFERROR(IF(試作シート3!B9="","",試作シート3!B9),"")
A5: =ROW()-1 -> 4 | B5: =IF(ISERROR(試作シート4!$A$1),"",HYPERLINK("#'試作シート4'!A1","試作シート4")) -> 試作シート4 | C5: =IF(ISERROR(試作シート4!$A$1),"",IF(OR(表紙!$D$4="",試作シート4!$D$4="",試作シート4!$B$5="",試作シート4!$D$5=""),"(入力待ち)",表紙!$D$4&"_"&試作シート4!$D$4&"_"&TEXT(試作シート4!$B$5,"yyyymmdd")&TEXT(試作シート4!$D$5,"hhmm")&"_"&A5)) -> RK_tnk_202608251400_4 | D5: =IFERROR(IF(試作シート4!B2="","",試作シート4!B2),"") -> 保存性向上（安定剤比較） | E5: =IFERROR(IF(試作シート4!B3="","",試作シート4!B3),"") -> 最終確定 | F5: =IFERROR(IF(試作シート4!B4="","",試作シート4!B4),"") -> 山田 太郎 | G5: =IFERROR(IF(試作シート4!D4="","",試作シート4!D4),"") -> tnk | H5: =IFERROR(IF(試作シート4!B5="","",試作シート4!B5),"") -> 2026-08-25 | I5: =IFERROR(IF(試作シート4!D5="","",試作シート4!D5),"") -> 14:00 | J5: =IFERROR(IF(試作シート4!B6="","",試作シート4!B6),"") -> 2026-09-01 | K5: =IFERROR(IF(試作シート4!D6="","",試作シート4!D6),"") -> 15:00 | L5: =IFERROR(IF(試作シート4!B7="","",試作シート4!B7),"") -> 2026-09-01 | M5: =IFERROR(IF(試作シート4!B8="","",試作シート4!B8),"") -> 流通期間延長のため氷結晶成長の抑制を狙う。 | N5: =IFERROR(IF(試作シート4!B9="","",試作シート4!B9),"") -> 安定剤B 0.2%配合で氷結晶の粗大化を抑制、採用決定。
A6: =ROW()-1 -> 5 | B6: =IF(ISERROR('試作シート5'!$a$1),"",HYPERLINK("#'試作シート5'!A1","試作シート5")) | C6: =IF(ISERROR('試作シート5'!$a$1),"",IF(OR(表紙!$D$4="",'試作シート5'!$d$4="",'試作シート5'!$b$5="",'試作シート5'!$d$5=""),"(入力待ち)",表紙!$D$4&"_"&'試作シート5'!$d$4&"_"&TEXT('試作シート5'!$b$5,"yyyymmdd")&TEXT('試作シート5'!$d$5,"hhmm")&"_"&A6)) | D6: =IFERROR(IF('試作シート5'!b2="","",'試作シート5'!b2),"") | E6: =IFERROR(IF('試作シート5'!b3="","",'試作シート5'!b3),"") | F6: =IFERROR(IF('試作シート5'!b4="","",'試作シート5'!b4),"") | G6: =IFERROR(IF('試作シート5'!d4="","",'試作シート5'!d4),"") | H6: =IFERROR(IF('試作シート5'!b5="","",'試作シート5'!b5),"") | I6: =IFERROR(IF('試作シート5'!d5="","",'試作シート5'!d5),"") | J6: =IFERROR(IF('試作シート5'!b6="","",'試作シート5'!b6),"") | K6: =IFERROR(IF('試作シート5'!d6="","",'試作シート5'!d6),"") | L6: =IFERROR(IF('試作シート5'!b7="","",'試作シート5'!b7),"") | M6: =IFERROR(IF('試作シート5'!b8="","",'試作シート5'!b8),"") | N6: =IFERROR(IF('試作シート5'!b9="","",'試作シート5'!b9),"")
A7: =ROW()-1 -> 6 | B7: =IF(ISERROR('試作シート6'!$a$1),"",HYPERLINK("#'試作シート6'!A1","試作シート6")) | C7: =IF(ISERROR('試作シート6'!$a$1),"",IF(OR(表紙!$D$4="",'試作シート6'!$d$4="",'試作シート6'!$b$5="",'試作シート6'!$d$5=""),"(入力待ち)",表紙!$D$4&"_"&'試作シート6'!$d$4&"_"&TEXT('試作シート6'!$b$5,"yyyymmdd")&TEXT('試作シート6'!$d$5,"hhmm")&"_"&A7)) | D7: =IFERROR(IF('試作シート6'!b2="","",'試作シート6'!b2),"") | E7: =IFERROR(IF('試作シート6'!b3="","",'試作シート6'!b3),"") | F7: =IFERROR(IF('試作シート6'!b4="","",'試作シート6'!b4),"") | G7: =IFERROR(IF('試作シート6'!d4="","",'試作シート6'!d4),"") | H7: =IFERROR(IF('試作シート6'!b5="","",'試作シート6'!b5),"") | I7: =IFERROR(IF('試作シート6'!d5="","",'試作シート6'!d5),"") | J7: =IFERROR(IF('試作シート6'!b6="","",'試作シート6'!b6),"") | K7: =IFERROR(IF('試作シート6'!d6="","",'試作シート6'!d6),"") | L7: =IFERROR(IF('試作シート6'!b7="","",'試作シート6'!b7),"") | M7: =IFERROR(IF('試作シート6'!b8="","",'試作シート6'!b8),"") | N7: =IFERROR(IF('試作シート6'!b9="","",'試作シート6'!b9),"")
A8: =ROW()-1 -> 7 | B8: =IF(ISERROR('試作シート7'!$a$1),"",HYPERLINK("#'試作シート7'!A1","試作シート7")) | C8: =IF(ISERROR('試作シート7'!$a$1),"",IF(OR(表紙!$D$4="",'試作シート7'!$d$4="",'試作シート7'!$b$5="",'試作シート7'!$d$5=""),"(入力待ち)",表紙!$D$4&"_"&'試作シート7'!$d$4&"_"&TEXT('試作シート7'!$b$5,"yyyymmdd")&TEXT('試作シート7'!$d$5,"hhmm")&"_"&A8)) | D8: =IFERROR(IF('試作シート7'!b2="","",'試作シート7'!b2),"") | E8: =IFERROR(IF('試作シート7'!b3="","",'試作シート7'!b3),"") | F8: =IFERROR(IF('試作シート7'!b4="","",'試作シート7'!b4),"") | G8: =IFERROR(IF('試作シート7'!d4="","",'試作シート7'!d4),"") | H8: =IFERROR(IF('試作シート7'!b5="","",'試作シート7'!b5),"") | I8: =IFERROR(IF('試作シート7'!d5="","",'試作シート7'!d5),"") | J8: =IFERROR(IF('試作シート7'!b6="","",'試作シート7'!b6),"") | K8: =IFERROR(IF('試作シート7'!d6="","",'試作シート7'!d6),"") | L8: =IFERROR(IF('試作シート7'!b7="","",'試作シート7'!b7),"") | M8: =IFERROR(IF('試作シート7'!b8="","",'試作シート7'!b8),"") | N8: =IFERROR(IF('試作シート7'!b9="","",'試作シート7'!b9),"")
A9: =ROW()-1 -> 8 | B9: =IF(ISERROR('試作シート8'!$a$1),"",HYPERLINK("#'試作シート8'!A1","試作シート8")) | C9: =IF(ISERROR('試作シート8'!$a$1),"",IF(OR(表紙!$D$4="",'試作シート8'!$d$4="",'試作シート8'!$b$5="",'試作シート8'!$d$5=""),"(入力待ち)",表紙!$D$4&"_"&'試作シート8'!$d$4&"_"&TEXT('試作シート8'!$b$5,"yyyymmdd")&TEXT('試作シート8'!$d$5,"hhmm")&"_"&A9)) | D9: =IFERROR(IF('試作シート8'!b2="","",'試作シート8'!b2),"") | E9: =IFERROR(IF('試作シート8'!b3="","",'試作シート8'!b3),"") | F9: =IFERROR(IF('試作シート8'!b4="","",'試作シート8'!b4),"") | G9: =IFERROR(IF('試作シート8'!d4="","",'試作シート8'!d4),"") | H9: =IFERROR(IF('試作シート8'!b5="","",'試作シート8'!b5),"") | I9: =IFERROR(IF('試作シート8'!d5="","",'試作シート8'!d5),"") | J9: =IFERROR(IF('試作シート8'!b6="","",'試作シート8'!b6),"") | K9: =IFERROR(IF('試作シート8'!d6="","",'試作シート8'!d6),"") | L9: =IFERROR(IF('試作シート8'!b7="","",'試作シート8'!b7),"") | M9: =IFERROR(IF('試作シート8'!b8="","",'試作シート8'!b8),"") | N9: =IFERROR(IF('試作シート8'!b9="","",'試作シート8'!b9),"")
A10: =ROW()-1 -> 9 | B10: =IF(ISERROR('試作シート9'!$a$1),"",HYPERLINK("#'試作シート9'!A1","試作シート9")) | C10: =IF(ISERROR('試作シート9'!$a$1),"",IF(OR(表紙!$D$4="",'試作シート9'!$d$4="",'試作シート9'!$b$5="",'試作シート9'!$d$5=""),"(入力待ち)",表紙!$D$4&"_"&'試作シート9'!$d$4&"_"&TEXT('試作シート9'!$b$5,"yyyymmdd")&TEXT('試作シート9'!$d$5,"hhmm")&"_"&A10)) | D10: =IFERROR(IF('試作シート9'!b2="","",'試作シート9'!b2),"") | E10: =IFERROR(IF('試作シート9'!b3="","",'試作シート9'!b3),"") | F10: =IFERROR(IF('試作シート9'!b4="","",'試作シート9'!b4),"") | G10: =IFERROR(IF('試作シート9'!d4="","",'試作シート9'!d4),"") | H10: =IFERROR(IF('試作シート9'!b5="","",'試作シート9'!b5),"") | I10: =IFERROR(IF('試作シート9'!d5="","",'試作シート9'!d5),"") | J10: =IFERROR(IF('試作シート9'!b6="","",'試作シート9'!b6),"") | K10: =IFERROR(IF('試作シート9'!d6="","",'試作シート9'!d6),"") | L10: =IFERROR(IF('試作シート9'!b7="","",'試作シート9'!b7),"") | M10: =IFERROR(IF('試作シート9'!b8="","",'試作シート9'!b8),"") | N10: =IFERROR(IF('試作シート9'!b9="","",'試作シート9'!b9),"")
A11: =ROW()-1 -> 10 | B11: =IF(ISERROR('試作シート10'!$a$1),"",HYPERLINK("#'試作シート10'!A1","試作シート10")) | C11: =IF(ISERROR('試作シート10'!$a$1),"",IF(OR(表紙!$D$4="",'試作シート10'!$d$4="",'試作シート10'!$b$5="",'試作シート10'!$d$5=""),"(入力待ち)",表紙!$D$4&"_"&'試作シート10'!$d$4&"_"&TEXT('試作シート10'!$b$5,"yyyymmdd")&TEXT('試作シート10'!$d$5,"hhmm")&"_"&A11)) | D11: =IFERROR(IF('試作シート10'!b2="","",'試作シート10'!b2),"") | E11: =IFERROR(IF('試作シート10'!b3="","",'試作シート10'!b3),"") | F11: =IFERROR(IF('試作シート10'!b4="","",'試作シート10'!b4),"") | G11: =IFERROR(IF('試作シート10'!d4="","",'試作シート10'!d4),"") | H11: =IFERROR(IF('試作シート10'!b5="","",'試作シート10'!b5),"") | I11: =IFERROR(IF('試作シート10'!d5="","",'試作シート10'!d5),"") | J11: =IFERROR(IF('試作シート10'!b6="","",'試作シート10'!b6),"") | K11: =IFERROR(IF('試作シート10'!d6="","",'試作シート10'!d6),"") | L11: =IFERROR(IF('試作シート10'!b7="","",'試作シート10'!b7),"") | M11: =IFERROR(IF('試作シート10'!b8="","",'試作シート10'!b8),"") | N11: =IFERROR(IF('試作シート10'!b9="","",'試作シート10'!b9),"")
A12: =ROW()-1 -> 11 | B12: =IF(ISERROR('試作シート11'!$a$1),"",HYPERLINK("#'試作シート11'!A1","試作シート11")) | C12: =IF(ISERROR('試作シート11'!$a$1),"",IF(OR(表紙!$D$4="",'試作シート11'!$d$4="",'試作シート11'!$b$5="",'試作シート11'!$d$5=""),"(入力待ち)",表紙!$D$4&"_"&'試作シート11'!$d$4&"_"&TEXT('試作シート11'!$b$5,"yyyymmdd")&TEXT('試作シート11'!$d$5,"hhmm")&"_"&A12)) | D12: =IFERROR(IF('試作シート11'!b2="","",'試作シート11'!b2),"") | E12: =IFERROR(IF('試作シート11'!b3="","",'試作シート11'!b3),"") | F12: =IFERROR(IF('試作シート11'!b4="","",'試作シート11'!b4),"") | G12: =IFERROR(IF('試作シート11'!d4="","",'試作シート11'!d4),"") | H12: =IFERROR(IF('試作シート11'!b5="","",'試作シート11'!b5),"") | I12: =IFERROR(IF('試作シート11'!d5="","",'試作シート11'!d5),"") | J12: =IFERROR(IF('試作シート11'!b6="","",'試作シート11'!b6),"") | K12: =IFERROR(IF('試作シート11'!d6="","",'試作シート11'!d6),"") | L12: =IFERROR(IF('試作シート11'!b7="","",'試作シート11'!b7),"") | M12: =IFERROR(IF('試作シート11'!b8="","",'試作シート11'!b8),"") | N12: =IFERROR(IF('試作シート11'!b9="","",'試作シート11'!b9),"")
A13: =ROW()-1 -> 12 | B13: =IF(ISERROR('試作シート12'!$a$1),"",HYPERLINK("#'試作シート12'!A1","試作シート12")) | C13: =IF(ISERROR('試作シート12'!$a$1),"",IF(OR(表紙!$D$4="",'試作シート12'!$d$4="",'試作シート12'!$b$5="",'試作シート12'!$d$5=""),"(入力待ち)",表紙!$D$4&"_"&'試作シート12'!$d$4&"_"&TEXT('試作シート12'!$b$5,"yyyymmdd")&TEXT('試作シート12'!$d$5,"hhmm")&"_"&A13)) | D13: =IFERROR(IF('試作シート12'!b2="","",'試作シート12'!b2),"") | E13: =IFERROR(IF('試作シート12'!b3="","",'試作シート12'!b3),"") | F13: =IFERROR(IF('試作シート12'!b4="","",'試作シート12'!b4),"") | G13: =IFERROR(IF('試作シート12'!d4="","",'試作シート12'!d4),"") | H13: =IFERROR(IF('試作シート12'!b5="","",'試作シート12'!b5),"") | I13: =IFERROR(IF('試作シート12'!d5="","",'試作シート12'!d5),"") | J13: =IFERROR(IF('試作シート12'!b6="","",'試作シート12'!b6),"") | K13: =IFERROR(IF('試作シート12'!d6="","",'試作シート12'!d6),"") | L13: =IFERROR(IF('試作シート12'!b7="","",'試作シート12'!b7),"") | M13: =IFERROR(IF('試作シート12'!b8="","",'試作シート12'!b8),"") | N13: =IFERROR(IF('試作シート12'!b9="","",'試作シート12'!b9),"")
A14: =ROW()-1 -> 13 | B14: =IF(ISERROR('試作シート13'!$a$1),"",HYPERLINK("#'試作シート13'!A1","試作シート13")) | C14: =IF(ISERROR('試作シート13'!$a$1),"",IF(OR(表紙!$D$4="",'試作シート13'!$d$4="",'試作シート13'!$b$5="",'試作シート13'!$d$5=""),"(入力待ち)",表紙!$D$4&"_"&'試作シート13'!$d$4&"_"&TEXT('試作シート13'!$b$5,"yyyymmdd")&TEXT('試作シート13'!$d$5,"hhmm")&"_"&A14)) | D14: =IFERROR(IF('試作シート13'!b2="","",'試作シート13'!b2),"") | E14: =IFERROR(IF('試作シート13'!b3="","",'試作シート13'!b3),"") | F14: =IFERROR(IF('試作シート13'!b4="","",'試作シート13'!b4),"") | G14: =IFERROR(IF('試作シート13'!d4="","",'試作シート13'!d4),"") | H14: =IFERROR(IF('試作シート13'!b5="","",'試作シート13'!b5),"") | I14: =IFERROR(IF('試作シート13'!d5="","",'試作シート13'!d5),"") | J14: =IFERROR(IF('試作シート13'!b6="","",'試作シート13'!b6),"") | K14: =IFERROR(IF('試作シート13'!d6="","",'試作シート13'!d6),"") | L14: =IFERROR(IF('試作シート13'!b7="","",'試作シート13'!b7),"") | M14: =IFERROR(IF('試作シート13'!b8="","",'試作シート13'!b8),"") | N14: =IFERROR(IF('試作シート13'!b9="","",'試作シート13'!b9),"")
A15: =ROW()-1 -> 14 | B15: =IF(ISERROR('試作シート14'!$a$1),"",HYPERLINK("#'試作シート14'!A1","試作シート14")) | C15: =IF(ISERROR('試作シート14'!$a$1),"",IF(OR(表紙!$D$4="",'試作シート14'!$d$4="",'試作シート14'!$b$5="",'試作シート14'!$d$5=""),"(入力待ち)",表紙!$D$4&"_"&'試作シート14'!$d$4&"_"&TEXT('試作シート14'!$b$5,"yyyymmdd")&TEXT('試作シート14'!$d$5,"hhmm")&"_"&A15)) | D15: =IFERROR(IF('試作シート14'!b2="","",'試作シート14'!b2),"") | E15: =IFERROR(IF('試作シート14'!b3="","",'試作シート14'!b3),"") | F15: =IFERROR(IF('試作シート14'!b4="","",'試作シート14'!b4),"") | G15: =IFERROR(IF('試作シート14'!d4="","",'試作シート14'!d4),"") | H15: =IFERROR(IF('試作シート14'!b5="","",'試作シート14'!b5),"") | I15: =IFERROR(IF('試作シート14'!d5="","",'試作シート14'!d5),"") | J15: =IFERROR(IF('試作シート14'!b6="","",'試作シート14'!b6),"") | K15: =IFERROR(IF('試作シート14'!d6="","",'試作シート14'!d6),"") | L15: =IFERROR(IF('試作シート14'!b7="","",'試作シート14'!b7),"") | M15: =IFERROR(IF('試作シート14'!b8="","",'試作シート14'!b8),"") | N15: =IFERROR(IF('試作シート14'!b9="","",'試作シート14'!b9),"")
A16: =ROW()-1 -> 15 | B16: =IF(ISERROR('試作シート15'!$a$1),"",HYPERLINK("#'試作シート15'!A1","試作シート15")) | C16: =IF(ISERROR('試作シート15'!$a$1),"",IF(OR(表紙!$D$4="",'試作シート15'!$d$4="",'試作シート15'!$b$5="",'試作シート15'!$d$5=""),"(入力待ち)",表紙!$D$4&"_"&'試作シート15'!$d$4&"_"&TEXT('試作シート15'!$b$5,"yyyymmdd")&TEXT('試作シート15'!$d$5,"hhmm")&"_"&A16)) | D16: =IFERROR(IF('試作シート15'!b2="","",'試作シート15'!b2),"") | E16: =IFERROR(IF('試作シート15'!b3="","",'試作シート15'!b3),"") | F16: =IFERROR(IF('試作シート15'!b4="","",'試作シート15'!b4),"") | G16: =IFERROR(IF('試作シート15'!d4="","",'試作シート15'!d4),"") | H16: =IFERROR(IF('試作シート15'!b5="","",'試作シート15'!b5),"") | I16: =IFERROR(IF('試作シート15'!d5="","",'試作シート15'!d5),"") | J16: =IFERROR(IF('試作シート15'!b6="","",'試作シート15'!b6),"") | K16: =IFERROR(IF('試作シート15'!d6="","",'試作シート15'!d6),"") | L16: =IFERROR(IF('試作シート15'!b7="","",'試作シート15'!b7),"") | M16: =IFERROR(IF('試作シート15'!b8="","",'試作シート15'!b8),"") | N16: =IFERROR(IF('試作シート15'!b9="","",'試作シート15'!b9),"")
A17: =ROW()-1 -> 16 | B17: =IF(ISERROR('試作シート16'!$a$1),"",HYPERLINK("#'試作シート16'!A1","試作シート16")) | C17: =IF(ISERROR('試作シート16'!$a$1),"",IF(OR(表紙!$D$4="",'試作シート16'!$d$4="",'試作シート16'!$b$5="",'試作シート16'!$d$5=""),"(入力待ち)",表紙!$D$4&"_"&'試作シート16'!$d$4&"_"&TEXT('試作シート16'!$b$5,"yyyymmdd")&TEXT('試作シート16'!$d$5,"hhmm")&"_"&A17)) | D17: =IFERROR(IF('試作シート16'!b2="","",'試作シート16'!b2),"") | E17: =IFERROR(IF('試作シート16'!b3="","",'試作シート16'!b3),"") | F17: =IFERROR(IF('試作シート16'!b4="","",'試作シート16'!b4),"") | G17: =IFERROR(IF('試作シート16'!d4="","",'試作シート16'!d4),"") | H17: =IFERROR(IF('試作シート16'!b5="","",'試作シート16'!b5),"") | I17: =IFERROR(IF('試作シート16'!d5="","",'試作シート16'!d5),"") | J17: =IFERROR(IF('試作シート16'!b6="","",'試作シート16'!b6),"") | K17: =IFERROR(IF('試作シート16'!d6="","",'試作シート16'!d6),"") | L17: =IFERROR(IF('試作シート16'!b7="","",'試作シート16'!b7),"") | M17: =IFERROR(IF('試作シート16'!b8="","",'試作シート16'!b8),"") | N17: =IFERROR(IF('試作シート16'!b9="","",'試作シート16'!b9),"")
A18: =ROW()-1 -> 17 | B18: =IF(ISERROR('試作シート17'!$a$1),"",HYPERLINK("#'試作シート17'!A1","試作シート17")) | C18: =IF(ISERROR('試作シート17'!$a$1),"",IF(OR(表紙!$D$4="",'試作シート17'!$d$4="",'試作シート17'!$b$5="",'試作シート17'!$d$5=""),"(入力待ち)",表紙!$D$4&"_"&'試作シート17'!$d$4&"_"&TEXT('試作シート17'!$b$5,"yyyymmdd")&TEXT('試作シート17'!$d$5,"hhmm")&"_"&A18)) | D18: =IFERROR(IF('試作シート17'!b2="","",'試作シート17'!b2),"") | E18: =IFERROR(IF('試作シート17'!b3="","",'試作シート17'!b3),"") | F18: =IFERROR(IF('試作シート17'!b4="","",'試作シート17'!b4),"") | G18: =IFERROR(IF('試作シート17'!d4="","",'試作シート17'!d4),"") | H18: =IFERROR(IF('試作シート17'!b5="","",'試作シート17'!b5),"") | I18: =IFERROR(IF('試作シート17'!d5="","",'試作シート17'!d5),"") | J18: =IFERROR(IF('試作シート17'!b6="","",'試作シート17'!b6),"") | K18: =IFERROR(IF('試作シート17'!d6="","",'試作シート17'!d6),"") | L18: =IFERROR(IF('試作シート17'!b7="","",'試作シート17'!b7),"") | M18: =IFERROR(IF('試作シート17'!b8="","",'試作シート17'!b8),"") | N18: =IFERROR(IF('試作シート17'!b9="","",'試作シート17'!b9),"")
A19: =ROW()-1 -> 18 | B19: =IF(ISERROR('試作シート18'!$a$1),"",HYPERLINK("#'試作シート18'!A1","試作シート18")) | C19: =IF(ISERROR('試作シート18'!$a$1),"",IF(OR(表紙!$D$4="",'試作シート18'!$d$4="",'試作シート18'!$b$5="",'試作シート18'!$d$5=""),"(入力待ち)",表紙!$D$4&"_"&'試作シート18'!$d$4&"_"&TEXT('試作シート18'!$b$5,"yyyymmdd")&TEXT('試作シート18'!$d$5,"hhmm")&"_"&A19)) | D19: =IFERROR(IF('試作シート18'!b2="","",'試作シート18'!b2),"") | E19: =IFERROR(IF('試作シート18'!b3="","",'試作シート18'!b3),"") | F19: =IFERROR(IF('試作シート18'!b4="","",'試作シート18'!b4),"") | G19: =IFERROR(IF('試作シート18'!d4="","",'試作シート18'!d4),"") | H19: =IFERROR(IF('試作シート18'!b5="","",'試作シート18'!b5),"") | I19: =IFERROR(IF('試作シート18'!d5="","",'試作シート18'!d5),"") | J19: =IFERROR(IF('試作シート18'!b6="","",'試作シート18'!b6),"") | K19: =IFERROR(IF('試作シート18'!d6="","",'試作シート18'!d6),"") | L19: =IFERROR(IF('試作シート18'!b7="","",'試作シート18'!b7),"") | M19: =IFERROR(IF('試作シート18'!b8="","",'試作シート18'!b8),"") | N19: =IFERROR(IF('試作シート18'!b9="","",'試作シート18'!b9),"")
A20: =ROW()-1 -> 19 | B20: =IF(ISERROR('試作シート19'!$a$1),"",HYPERLINK("#'試作シート19'!A1","試作シート19")) | C20: =IF(ISERROR('試作シート19'!$a$1),"",IF(OR(表紙!$D$4="",'試作シート19'!$d$4="",'試作シート19'!$b$5="",'試作シート19'!$d$5=""),"(入力待ち)",表紙!$D$4&"_"&'試作シート19'!$d$4&"_"&TEXT('試作シート19'!$b$5,"yyyymmdd")&TEXT('試作シート19'!$d$5,"hhmm")&"_"&A20)) | D20: =IFERROR(IF('試作シート19'!b2="","",'試作シート19'!b2),"") | E20: =IFERROR(IF('試作シート19'!b3="","",'試作シート19'!b3),"") | F20: =IFERROR(IF('試作シート19'!b4="","",'試作シート19'!b4),"") | G20: =IFERROR(IF('試作シート19'!d4="","",'試作シート19'!d4),"") | H20: =IFERROR(IF('試作シート19'!b5="","",'試作シート19'!b5),"") | I20: =IFERROR(IF('試作シート19'!d5="","",'試作シート19'!d5),"") | J20: =IFERROR(IF('試作シート19'!b6="","",'試作シート19'!b6),"") | K20: =IFERROR(IF('試作シート19'!d6="","",'試作シート19'!d6),"") | L20: =IFERROR(IF('試作シート19'!b7="","",'試作シート19'!b7),"") | M20: =IFERROR(IF('試作シート19'!b8="","",'試作シート19'!b8),"") | N20: =IFERROR(IF('試作シート19'!b9="","",'試作シート19'!b9),"")
A21: =ROW()-1 -> 20 | B21: =IF(ISERROR('試作シート20'!$a$1),"",HYPERLINK("#'試作シート20'!A1","試作シート20")) | C21: =IF(ISERROR('試作シート20'!$a$1),"",IF(OR(表紙!$D$4="",'試作シート20'!$d$4="",'試作シート20'!$b$5="",'試作シート20'!$d$5=""),"(入力待ち)",表紙!$D$4&"_"&'試作シート20'!$d$4&"_"&TEXT('試作シート20'!$b$5,"yyyymmdd")&TEXT('試作シート20'!$d$5,"hhmm")&"_"&A21)) | D21: =IFERROR(IF('試作シート20'!b2="","",'試作シート20'!b2),"") | E21: =IFERROR(IF('試作シート20'!b3="","",'試作シート20'!b3),"") | F21: =IFERROR(IF('試作シート20'!b4="","",'試作シート20'!b4),"") | G21: =IFERROR(IF('試作シート20'!d4="","",'試作シート20'!d4),"") | H21: =IFERROR(IF('試作シート20'!b5="","",'試作シート20'!b5),"") | I21: =IFERROR(IF('試作シート20'!d5="","",'試作シート20'!d5),"") | J21: =IFERROR(IF('試作シート20'!b6="","",'試作シート20'!b6),"") | K21: =IFERROR(IF('試作シート20'!d6="","",'試作シート20'!d6),"") | L21: =IFERROR(IF('試作シート20'!b7="","",'試作シート20'!b7),"") | M21: =IFERROR(IF('試作シート20'!b8="","",'試作シート20'!b8),"") | N21: =IFERROR(IF('試作シート20'!b9="","",'試作シート20'!b9),"")
A22: =ROW()-1 -> 21 | B22: =IF(ISERROR('試作シート21'!$a$1),"",HYPERLINK("#'試作シート21'!A1","試作シート21")) | C22: =IF(ISERROR('試作シート21'!$a$1),"",IF(OR(表紙!$D$4="",'試作シート21'!$d$4="",'試作シート21'!$b$5="",'試作シート21'!$d$5=""),"(入力待ち)",表紙!$D$4&"_"&'試作シート21'!$d$4&"_"&TEXT('試作シート21'!$b$5,"yyyymmdd")&TEXT('試作シート21'!$d$5,"hhmm")&"_"&A22)) | D22: =IFERROR(IF('試作シート21'!b2="","",'試作シート21'!b2),"") | E22: =IFERROR(IF('試作シート21'!b3="","",'試作シート21'!b3),"") | F22: =IFERROR(IF('試作シート21'!b4="","",'試作シート21'!b4),"") | G22: =IFERROR(IF('試作シート21'!d4="","",'試作シート21'!d4),"") | H22: =IFERROR(IF('試作シート21'!b5="","",'試作シート21'!b5),"") | I22: =IFERROR(IF('試作シート21'!d5="","",'試作シート21'!d5),"") | J22: =IFERROR(IF('試作シート21'!b6="","",'試作シート21'!b6),"") | K22: =IFERROR(IF('試作シート21'!d6="","",'試作シート21'!d6),"") | L22: =IFERROR(IF('試作シート21'!b7="","",'試作シート21'!b7),"") | M22: =IFERROR(IF('試作シート21'!b8="","",'試作シート21'!b8),"") | N22: =IFERROR(IF('試作シート21'!b9="","",'試作シート21'!b9),"")
A23: =ROW()-1 -> 22 | B23: =IF(ISERROR('試作シート22'!$a$1),"",HYPERLINK("#'試作シート22'!A1","試作シート22")) | C23: =IF(ISERROR('試作シート22'!$a$1),"",IF(OR(表紙!$D$4="",'試作シート22'!$d$4="",'試作シート22'!$b$5="",'試作シート22'!$d$5=""),"(入力待ち)",表紙!$D$4&"_"&'試作シート22'!$d$4&"_"&TEXT('試作シート22'!$b$5,"yyyymmdd")&TEXT('試作シート22'!$d$5,"hhmm")&"_"&A23)) | D23: =IFERROR(IF('試作シート22'!b2="","",'試作シート22'!b2),"") | E23: =IFERROR(IF('試作シート22'!b3="","",'試作シート22'!b3),"") | F23: =IFERROR(IF('試作シート22'!b4="","",'試作シート22'!b4),"") | G23: =IFERROR(IF('試作シート22'!d4="","",'試作シート22'!d4),"") | H23: =IFERROR(IF('試作シート22'!b5="","",'試作シート22'!b5),"") | I23: =IFERROR(IF('試作シート22'!d5="","",'試作シート22'!d5),"") | J23: =IFERROR(IF('試作シート22'!b6="","",'試作シート22'!b6),"") | K23: =IFERROR(IF('試作シート22'!d6="","",'試作シート22'!d6),"") | L23: =IFERROR(IF('試作シート22'!b7="","",'試作シート22'!b7),"") | M23: =IFERROR(IF('試作シート22'!b8="","",'試作シート22'!b8),"") | N23: =IFERROR(IF('試作シート22'!b9="","",'試作シート22'!b9),"")
A24: =ROW()-1 -> 23 | B24: =IF(ISERROR('試作シート23'!$a$1),"",HYPERLINK("#'試作シート23'!A1","試作シート23")) | C24: =IF(ISERROR('試作シート23'!$a$1),"",IF(OR(表紙!$D$4="",'試作シート23'!$d$4="",'試作シート23'!$b$5="",'試作シート23'!$d$5=""),"(入力待ち)",表紙!$D$4&"_"&'試作シート23'!$d$4&"_"&TEXT('試作シート23'!$b$5,"yyyymmdd")&TEXT('試作シート23'!$d$5,"hhmm")&"_"&A24)) | D24: =IFERROR(IF('試作シート23'!b2="","",'試作シート23'!b2),"") | E24: =IFERROR(IF('試作シート23'!b3="","",'試作シート23'!b3),"") | F24: =IFERROR(IF('試作シート23'!b4="","",'試作シート23'!b4),"") | G24: =IFERROR(IF('試作シート23'!d4="","",'試作シート23'!d4),"") | H24: =IFERROR(IF('試作シート23'!b5="","",'試作シート23'!b5),"") | I24: =IFERROR(IF('試作シート23'!d5="","",'試作シート23'!d5),"") | J24: =IFERROR(IF('試作シート23'!b6="","",'試作シート23'!b6),"") | K24: =IFERROR(IF('試作シート23'!d6="","",'試作シート23'!d6),"") | L24: =IFERROR(IF('試作シート23'!b7="","",'試作シート23'!b7),"") | M24: =IFERROR(IF('試作シート23'!b8="","",'試作シート23'!b8),"") | N24: =IFERROR(IF('試作シート23'!b9="","",'試作シート23'!b9),"")
A25: =ROW()-1 -> 24 | B25: =IF(ISERROR('試作シート24'!$a$1),"",HYPERLINK("#'試作シート24'!A1","試作シート24")) | C25: =IF(ISERROR('試作シート24'!$a$1),"",IF(OR(表紙!$D$4="",'試作シート24'!$d$4="",'試作シート24'!$b$5="",'試作シート24'!$d$5=""),"(入力待ち)",表紙!$D$4&"_"&'試作シート24'!$d$4&"_"&TEXT('試作シート24'!$b$5,"yyyymmdd")&TEXT('試作シート24'!$d$5,"hhmm")&"_"&A25)) | D25: =IFERROR(IF('試作シート24'!b2="","",'試作シート24'!b2),"") | E25: =IFERROR(IF('試作シート24'!b3="","",'試作シート24'!b3),"") | F25: =IFERROR(IF('試作シート24'!b4="","",'試作シート24'!b4),"") | G25: =IFERROR(IF('試作シート24'!d4="","",'試作シート24'!d4),"") | H25: =IFERROR(IF('試作シート24'!b5="","",'試作シート24'!b5),"") | I25: =IFERROR(IF('試作シート24'!d5="","",'試作シート24'!d5),"") | J25: =IFERROR(IF('試作シート24'!b6="","",'試作シート24'!b6),"") | K25: =IFERROR(IF('試作シート24'!d6="","",'試作シート24'!d6),"") | L25: =IFERROR(IF('試作シート24'!b7="","",'試作シート24'!b7),"") | M25: =IFERROR(IF('試作シート24'!b8="","",'試作シート24'!b8),"") | N25: =IFERROR(IF('試作シート24'!b9="","",'試作シート24'!b9),"")
A26: =ROW()-1 -> 25 | B26: =IF(ISERROR('試作シート25'!$a$1),"",HYPERLINK("#'試作シート25'!A1","試作シート25")) | C26: =IF(ISERROR('試作シート25'!$a$1),"",IF(OR(表紙!$D$4="",'試作シート25'!$d$4="",'試作シート25'!$b$5="",'試作シート25'!$d$5=""),"(入力待ち)",表紙!$D$4&"_"&'試作シート25'!$d$4&"_"&TEXT('試作シート25'!$b$5,"yyyymmdd")&TEXT('試作シート25'!$d$5,"hhmm")&"_"&A26)) | D26: =IFERROR(IF('試作シート25'!b2="","",'試作シート25'!b2),"") | E26: =IFERROR(IF('試作シート25'!b3="","",'試作シート25'!b3),"") | F26: =IFERROR(IF('試作シート25'!b4="","",'試作シート25'!b4),"") | G26: =IFERROR(IF('試作シート25'!d4="","",'試作シート25'!d4),"") | H26: =IFERROR(IF('試作シート25'!b5="","",'試作シート25'!b5),"") | I26: =IFERROR(IF('試作シート25'!d5="","",'試作シート25'!d5),"") | J26: =IFERROR(IF('試作シート25'!b6="","",'試作シート25'!b6),"") | K26: =IFERROR(IF('試作シート25'!d6="","",'試作シート25'!d6),"") | L26: =IFERROR(IF('試作シート25'!b7="","",'試作シート25'!b7),"") | M26: =IFERROR(IF('試作シート25'!b8="","",'試作シート25'!b8),"") | N26: =IFERROR(IF('試作シート25'!b9="","",'試作シート25'!b9),"")
A27: =ROW()-1 -> 26 | B27: =IF(ISERROR('試作シート26'!$a$1),"",HYPERLINK("#'試作シート26'!A1","試作シート26")) | C27: =IF(ISERROR('試作シート26'!$a$1),"",IF(OR(表紙!$D$4="",'試作シート26'!$d$4="",'試作シート26'!$b$5="",'試作シート26'!$d$5=""),"(入力待ち)",表紙!$D$4&"_"&'試作シート26'!$d$4&"_"&TEXT('試作シート26'!$b$5,"yyyymmdd")&TEXT('試作シート26'!$d$5,"hhmm")&"_"&A27)) | D27: =IFERROR(IF('試作シート26'!b2="","",'試作シート26'!b2),"") | E27: =IFERROR(IF('試作シート26'!b3="","",'試作シート26'!b3),"") | F27: =IFERROR(IF('試作シート26'!b4="","",'試作シート26'!b4),"") | G27: =IFERROR(IF('試作シート26'!d4="","",'試作シート26'!d4),"") | H27: =IFERROR(IF('試作シート26'!b5="","",'試作シート26'!b5),"") | I27: =IFERROR(IF('試作シート26'!d5="","",'試作シート26'!d5),"") | J27: =IFERROR(IF('試作シート26'!b6="","",'試作シート26'!b6),"") | K27: =IFERROR(IF('試作シート26'!d6="","",'試作シート26'!d6),"") | L27: =IFERROR(IF('試作シート26'!b7="","",'試作シート26'!b7),"") | M27: =IFERROR(IF('試作シート26'!b8="","",'試作シート26'!b8),"") | N27: =IFERROR(IF('試作シート26'!b9="","",'試作シート26'!b9),"")
A28: =ROW()-1 -> 27 | B28: =IF(ISERROR('試作シート27'!$a$1),"",HYPERLINK("#'試作シート27'!A1","試作シート27")) | C28: =IF(ISERROR('試作シート27'!$a$1),"",IF(OR(表紙!$D$4="",'試作シート27'!$d$4="",'試作シート27'!$b$5="",'試作シート27'!$d$5=""),"(入力待ち)",表紙!$D$4&"_"&'試作シート27'!$d$4&"_"&TEXT('試作シート27'!$b$5,"yyyymmdd")&TEXT('試作シート27'!$d$5,"hhmm")&"_"&A28)) | D28: =IFERROR(IF('試作シート27'!b2="","",'試作シート27'!b2),"") | E28: =IFERROR(IF('試作シート27'!b3="","",'試作シート27'!b3),"") | F28: =IFERROR(IF('試作シート27'!b4="","",'試作シート27'!b4),"") | G28: =IFERROR(IF('試作シート27'!d4="","",'試作シート27'!d4),"") | H28: =IFERROR(IF('試作シート27'!b5="","",'試作シート27'!b5),"") | I28: =IFERROR(IF('試作シート27'!d5="","",'試作シート27'!d5),"") | J28: =IFERROR(IF('試作シート27'!b6="","",'試作シート27'!b6),"") | K28: =IFERROR(IF('試作シート27'!d6="","",'試作シート27'!d6),"") | L28: =IFERROR(IF('試作シート27'!b7="","",'試作シート27'!b7),"") | M28: =IFERROR(IF('試作シート27'!b8="","",'試作シート27'!b8),"") | N28: =IFERROR(IF('試作シート27'!b9="","",'試作シート27'!b9),"")
A29: =ROW()-1 -> 28 | B29: =IF(ISERROR('試作シート28'!$a$1),"",HYPERLINK("#'試作シート28'!A1","試作シート28")) | C29: =IF(ISERROR('試作シート28'!$a$1),"",IF(OR(表紙!$D$4="",'試作シート28'!$d$4="",'試作シート28'!$b$5="",'試作シート28'!$d$5=""),"(入力待ち)",表紙!$D$4&"_"&'試作シート28'!$d$4&"_"&TEXT('試作シート28'!$b$5,"yyyymmdd")&TEXT('試作シート28'!$d$5,"hhmm")&"_"&A29)) | D29: =IFERROR(IF('試作シート28'!b2="","",'試作シート28'!b2),"") | E29: =IFERROR(IF('試作シート28'!b3="","",'試作シート28'!b3),"") | F29: =IFERROR(IF('試作シート28'!b4="","",'試作シート28'!b4),"") | G29: =IFERROR(IF('試作シート28'!d4="","",'試作シート28'!d4),"") | H29: =IFERROR(IF('試作シート28'!b5="","",'試作シート28'!b5),"") | I29: =IFERROR(IF('試作シート28'!d5="","",'試作シート28'!d5),"") | J29: =IFERROR(IF('試作シート28'!b6="","",'試作シート28'!b6),"") | K29: =IFERROR(IF('試作シート28'!d6="","",'試作シート28'!d6),"") | L29: =IFERROR(IF('試作シート28'!b7="","",'試作シート28'!b7),"") | M29: =IFERROR(IF('試作シート28'!b8="","",'試作シート28'!b8),"") | N29: =IFERROR(IF('試作シート28'!b9="","",'試作シート28'!b9),"")
A30: =ROW()-1 -> 29 | B30: =IF(ISERROR('試作シート29'!$a$1),"",HYPERLINK("#'試作シート29'!A1","試作シート29")) | C30: =IF(ISERROR('試作シート29'!$a$1),"",IF(OR(表紙!$D$4="",'試作シート29'!$d$4="",'試作シート29'!$b$5="",'試作シート29'!$d$5=""),"(入力待ち)",表紙!$D$4&"_"&'試作シート29'!$d$4&"_"&TEXT('試作シート29'!$b$5,"yyyymmdd")&TEXT('試作シート29'!$d$5,"hhmm")&"_"&A30)) | D30: =IFERROR(IF('試作シート29'!b2="","",'試作シート29'!b2),"") | E30: =IFERROR(IF('試作シート29'!b3="","",'試作シート29'!b3),"") | F30: =IFERROR(IF('試作シート29'!b4="","",'試作シート29'!b4),"") | G30: =IFERROR(IF('試作シート29'!d4="","",'試作シート29'!d4),"") | H30: =IFERROR(IF('試作シート29'!b5="","",'試作シート29'!b5),"") | I30: =IFERROR(IF('試作シート29'!d5="","",'試作シート29'!d5),"") | J30: =IFERROR(IF('試作シート29'!b6="","",'試作シート29'!b6),"") | K30: =IFERROR(IF('試作シート29'!d6="","",'試作シート29'!d6),"") | L30: =IFERROR(IF('試作シート29'!b7="","",'試作シート29'!b7),"") | M30: =IFERROR(IF('試作シート29'!b8="","",'試作シート29'!b8),"") | N30: =IFERROR(IF('試作シート29'!b9="","",'試作シート29'!b9),"")
A31: =ROW()-1 -> 30 | B31: =IF(ISERROR('試作シート30'!$a$1),"",HYPERLINK("#'試作シート30'!A1","試作シート30")) | C31: =IF(ISERROR('試作シート30'!$a$1),"",IF(OR(表紙!$D$4="",'試作シート30'!$d$4="",'試作シート30'!$b$5="",'試作シート30'!$d$5=""),"(入力待ち)",表紙!$D$4&"_"&'試作シート30'!$d$4&"_"&TEXT('試作シート30'!$b$5,"yyyymmdd")&TEXT('試作シート30'!$d$5,"hhmm")&"_"&A31)) | D31: =IFERROR(IF('試作シート30'!b2="","",'試作シート30'!b2),"") | E31: =IFERROR(IF('試作シート30'!b3="","",'試作シート30'!b3),"") | F31: =IFERROR(IF('試作シート30'!b4="","",'試作シート30'!b4),"") | G31: =IFERROR(IF('試作シート30'!d4="","",'試作シート30'!d4),"") | H31: =IFERROR(IF('試作シート30'!b5="","",'試作シート30'!b5),"") | I31: =IFERROR(IF('試作シート30'!d5="","",'試作シート30'!d5),"") | J31: =IFERROR(IF('試作シート30'!b6="","",'試作シート30'!b6),"") | K31: =IFERROR(IF('試作シート30'!d6="","",'試作シート30'!d6),"") | L31: =IFERROR(IF('試作シート30'!b7="","",'試作シート30'!b7),"") | M31: =IFERROR(IF('試作シート30'!b8="","",'試作シート30'!b8),"") | N31: =IFERROR(IF('試作シート30'!b9="","",'試作シート30'!b9),"")
A32: =ROW()-1 -> 31 | B32: =IF(ISERROR('試作シート31'!$a$1),"",HYPERLINK("#'試作シート31'!A1","試作シート31")) | C32: =IF(ISERROR('試作シート31'!$a$1),"",IF(OR(表紙!$D$4="",'試作シート31'!$d$4="",'試作シート31'!$b$5="",'試作シート31'!$d$5=""),"(入力待ち)",表紙!$D$4&"_"&'試作シート31'!$d$4&"_"&TEXT('試作シート31'!$b$5,"yyyymmdd")&TEXT('試作シート31'!$d$5,"hhmm")&"_"&A32)) | D32: =IFERROR(IF('試作シート31'!b2="","",'試作シート31'!b2),"") | E32: =IFERROR(IF('試作シート31'!b3="","",'試作シート31'!b3),"") | F32: =IFERROR(IF('試作シート31'!b4="","",'試作シート31'!b4),"") | G32: =IFERROR(IF('試作シート31'!d4="","",'試作シート31'!d4),"") | H32: =IFERROR(IF('試作シート31'!b5="","",'試作シート31'!b5),"") | I32: =IFERROR(IF('試作シート31'!d5="","",'試作シート31'!d5),"") | J32: =IFERROR(IF('試作シート31'!b6="","",'試作シート31'!b6),"") | K32: =IFERROR(IF('試作シート31'!d6="","",'試作シート31'!d6),"") | L32: =IFERROR(IF('試作シート31'!b7="","",'試作シート31'!b7),"") | M32: =IFERROR(IF('試作シート31'!b8="","",'試作シート31'!b8),"") | N32: =IFERROR(IF('試作シート31'!b9="","",'試作シート31'!b9),"")
A33: =ROW()-1 -> 32 | B33: =IF(ISERROR('試作シート32'!$a$1),"",HYPERLINK("#'試作シート32'!A1","試作シート32")) | C33: =IF(ISERROR('試作シート32'!$a$1),"",IF(OR(表紙!$D$4="",'試作シート32'!$d$4="",'試作シート32'!$b$5="",'試作シート32'!$d$5=""),"(入力待ち)",表紙!$D$4&"_"&'試作シート32'!$d$4&"_"&TEXT('試作シート32'!$b$5,"yyyymmdd")&TEXT('試作シート32'!$d$5,"hhmm")&"_"&A33)) | D33: =IFERROR(IF('試作シート32'!b2="","",'試作シート32'!b2),"") | E33: =IFERROR(IF('試作シート32'!b3="","",'試作シート32'!b3),"") | F33: =IFERROR(IF('試作シート32'!b4="","",'試作シート32'!b4),"") | G33: =IFERROR(IF('試作シート32'!d4="","",'試作シート32'!d4),"") | H33: =IFERROR(IF('試作シート32'!b5="","",'試作シート32'!b5),"") | I33: =IFERROR(IF('試作シート32'!d5="","",'試作シート32'!d5),"") | J33: =IFERROR(IF('試作シート32'!b6="","",'試作シート32'!b6),"") | K33: =IFERROR(IF('試作シート32'!d6="","",'試作シート32'!d6),"") | L33: =IFERROR(IF('試作シート32'!b7="","",'試作シート32'!b7),"") | M33: =IFERROR(IF('試作シート32'!b8="","",'試作シート32'!b8),"") | N33: =IFERROR(IF('試作シート32'!b9="","",'試作シート32'!b9),"")
A34: =ROW()-1 -> 33 | B34: =IF(ISERROR('試作シート33'!$a$1),"",HYPERLINK("#'試作シート33'!A1","試作シート33")) | C34: =IF(ISERROR('試作シート33'!$a$1),"",IF(OR(表紙!$D$4="",'試作シート33'!$d$4="",'試作シート33'!$b$5="",'試作シート33'!$d$5=""),"(入力待ち)",表紙!$D$4&"_"&'試作シート33'!$d$4&"_"&TEXT('試作シート33'!$b$5,"yyyymmdd")&TEXT('試作シート33'!$d$5,"hhmm")&"_"&A34)) | D34: =IFERROR(IF('試作シート33'!b2="","",'試作シート33'!b2),"") | E34: =IFERROR(IF('試作シート33'!b3="","",'試作シート33'!b3),"") | F34: =IFERROR(IF('試作シート33'!b4="","",'試作シート33'!b4),"") | G34: =IFERROR(IF('試作シート33'!d4="","",'試作シート33'!d4),"") | H34: =IFERROR(IF('試作シート33'!b5="","",'試作シート33'!b5),"") | I34: =IFERROR(IF('試作シート33'!d5="","",'試作シート33'!d5),"") | J34: =IFERROR(IF('試作シート33'!b6="","",'試作シート33'!b6),"") | K34: =IFERROR(IF('試作シート33'!d6="","",'試作シート33'!d6),"") | L34: =IFERROR(IF('試作シート33'!b7="","",'試作シート33'!b7),"") | M34: =IFERROR(IF('試作シート33'!b8="","",'試作シート33'!b8),"") | N34: =IFERROR(IF('試作シート33'!b9="","",'試作シート33'!b9),"")
A35: =ROW()-1 -> 34 | B35: =IF(ISERROR('試作シート34'!$a$1),"",HYPERLINK("#'試作シート34'!A1","試作シート34")) | C35: =IF(ISERROR('試作シート34'!$a$1),"",IF(OR(表紙!$D$4="",'試作シート34'!$d$4="",'試作シート34'!$b$5="",'試作シート34'!$d$5=""),"(入力待ち)",表紙!$D$4&"_"&'試作シート34'!$d$4&"_"&TEXT('試作シート34'!$b$5,"yyyymmdd")&TEXT('試作シート34'!$d$5,"hhmm")&"_"&A35)) | D35: =IFERROR(IF('試作シート34'!b2="","",'試作シート34'!b2),"") | E35: =IFERROR(IF('試作シート34'!b3="","",'試作シート34'!b3),"") | F35: =IFERROR(IF('試作シート34'!b4="","",'試作シート34'!b4),"") | G35: =IFERROR(IF('試作シート34'!d4="","",'試作シート34'!d4),"") | H35: =IFERROR(IF('試作シート34'!b5="","",'試作シート34'!b5),"") | I35: =IFERROR(IF('試作シート34'!d5="","",'試作シート34'!d5),"") | J35: =IFERROR(IF('試作シート34'!b6="","",'試作シート34'!b6),"") | K35: =IFERROR(IF('試作シート34'!d6="","",'試作シート34'!d6),"") | L35: =IFERROR(IF('試作シート34'!b7="","",'試作シート34'!b7),"") | M35: =IFERROR(IF('試作シート34'!b8="","",'試作シート34'!b8),"") | N35: =IFERROR(IF('試作シート34'!b9="","",'試作シート34'!b9),"")
A36: =ROW()-1 -> 35 | B36: =IF(ISERROR('試作シート35'!$a$1),"",HYPERLINK("#'試作シート35'!A1","試作シート35")) | C36: =IF(ISERROR('試作シート35'!$a$1),"",IF(OR(表紙!$D$4="",'試作シート35'!$d$4="",'試作シート35'!$b$5="",'試作シート35'!$d$5=""),"(入力待ち)",表紙!$D$4&"_"&'試作シート35'!$d$4&"_"&TEXT('試作シート35'!$b$5,"yyyymmdd")&TEXT('試作シート35'!$d$5,"hhmm")&"_"&A36)) | D36: =IFERROR(IF('試作シート35'!b2="","",'試作シート35'!b2),"") | E36: =IFERROR(IF('試作シート35'!b3="","",'試作シート35'!b3),"") | F36: =IFERROR(IF('試作シート35'!b4="","",'試作シート35'!b4),"") | G36: =IFERROR(IF('試作シート35'!d4="","",'試作シート35'!d4),"") | H36: =IFERROR(IF('試作シート35'!b5="","",'試作シート35'!b5),"") | I36: =IFERROR(IF('試作シート35'!d5="","",'試作シート35'!d5),"") | J36: =IFERROR(IF('試作シート35'!b6="","",'試作シート35'!b6),"") | K36: =IFERROR(IF('試作シート35'!d6="","",'試作シート35'!d6),"") | L36: =IFERROR(IF('試作シート35'!b7="","",'試作シート35'!b7),"") | M36: =IFERROR(IF('試作シート35'!b8="","",'試作シート35'!b8),"") | N36: =IFERROR(IF('試作シート35'!b9="","",'試作シート35'!b9),"")
A37: =ROW()-1 -> 36 | B37: =IF(ISERROR('試作シート36'!$a$1),"",HYPERLINK("#'試作シート36'!A1","試作シート36")) | C37: =IF(ISERROR('試作シート36'!$a$1),"",IF(OR(表紙!$D$4="",'試作シート36'!$d$4="",'試作シート36'!$b$5="",'試作シート36'!$d$5=""),"(入力待ち)",表紙!$D$4&"_"&'試作シート36'!$d$4&"_"&TEXT('試作シート36'!$b$5,"yyyymmdd")&TEXT('試作シート36'!$d$5,"hhmm")&"_"&A37)) | D37: =IFERROR(IF('試作シート36'!b2="","",'試作シート36'!b2),"") | E37: =IFERROR(IF('試作シート36'!b3="","",'試作シート36'!b3),"") | F37: =IFERROR(IF('試作シート36'!b4="","",'試作シート36'!b4),"") | G37: =IFERROR(IF('試作シート36'!d4="","",'試作シート36'!d4),"") | H37: =IFERROR(IF('試作シート36'!b5="","",'試作シート36'!b5),"") | I37: =IFERROR(IF('試作シート36'!d5="","",'試作シート36'!d5),"") | J37: =IFERROR(IF('試作シート36'!b6="","",'試作シート36'!b6),"") | K37: =IFERROR(IF('試作シート36'!d6="","",'試作シート36'!d6),"") | L37: =IFERROR(IF('試作シート36'!b7="","",'試作シート36'!b7),"") | M37: =IFERROR(IF('試作シート36'!b8="","",'試作シート36'!b8),"") | N37: =IFERROR(IF('試作シート36'!b9="","",'試作シート36'!b9),"")
A38: =ROW()-1 -> 37 | B38: =IF(ISERROR('試作シート37'!$a$1),"",HYPERLINK("#'試作シート37'!A1","試作シート37")) | C38: =IF(ISERROR('試作シート37'!$a$1),"",IF(OR(表紙!$D$4="",'試作シート37'!$d$4="",'試作シート37'!$b$5="",'試作シート37'!$d$5=""),"(入力待ち)",表紙!$D$4&"_"&'試作シート37'!$d$4&"_"&TEXT('試作シート37'!$b$5,"yyyymmdd")&TEXT('試作シート37'!$d$5,"hhmm")&"_"&A38)) | D38: =IFERROR(IF('試作シート37'!b2="","",'試作シート37'!b2),"") | E38: =IFERROR(IF('試作シート37'!b3="","",'試作シート37'!b3),"") | F38: =IFERROR(IF('試作シート37'!b4="","",'試作シート37'!b4),"") | G38: =IFERROR(IF('試作シート37'!d4="","",'試作シート37'!d4),"") | H38: =IFERROR(IF('試作シート37'!b5="","",'試作シート37'!b5),"") | I38: =IFERROR(IF('試作シート37'!d5="","",'試作シート37'!d5),"") | J38: =IFERROR(IF('試作シート37'!b6="","",'試作シート37'!b6),"") | K38: =IFERROR(IF('試作シート37'!d6="","",'試作シート37'!d6),"") | L38: =IFERROR(IF('試作シート37'!b7="","",'試作シート37'!b7),"") | M38: =IFERROR(IF('試作シート37'!b8="","",'試作シート37'!b8),"") | N38: =IFERROR(IF('試作シート37'!b9="","",'試作シート37'!b9),"")
A39: =ROW()-1 -> 38 | B39: =IF(ISERROR('試作シート38'!$a$1),"",HYPERLINK("#'試作シート38'!A1","試作シート38")) | C39: =IF(ISERROR('試作シート38'!$a$1),"",IF(OR(表紙!$D$4="",'試作シート38'!$d$4="",'試作シート38'!$b$5="",'試作シート38'!$d$5=""),"(入力待ち)",表紙!$D$4&"_"&'試作シート38'!$d$4&"_"&TEXT('試作シート38'!$b$5,"yyyymmdd")&TEXT('試作シート38'!$d$5,"hhmm")&"_"&A39)) | D39: =IFERROR(IF('試作シート38'!b2="","",'試作シート38'!b2),"") | E39: =IFERROR(IF('試作シート38'!b3="","",'試作シート38'!b3),"") | F39: =IFERROR(IF('試作シート38'!b4="","",'試作シート38'!b4),"") | G39: =IFERROR(IF('試作シート38'!d4="","",'試作シート38'!d4),"") | H39: =IFERROR(IF('試作シート38'!b5="","",'試作シート38'!b5),"") | I39: =IFERROR(IF('試作シート38'!d5="","",'試作シート38'!d5),"") | J39: =IFERROR(IF('試作シート38'!b6="","",'試作シート38'!b6),"") | K39: =IFERROR(IF('試作シート38'!d6="","",'試作シート38'!d6),"") | L39: =IFERROR(IF('試作シート38'!b7="","",'試作シート38'!b7),"") | M39: =IFERROR(IF('試作シート38'!b8="","",'試作シート38'!b8),"") | N39: =IFERROR(IF('試作シート38'!b9="","",'試作シート38'!b9),"")
A40: =ROW()-1 -> 39 | B40: =IF(ISERROR('試作シート39'!$a$1),"",HYPERLINK("#'試作シート39'!A1","試作シート39")) | C40: =IF(ISERROR('試作シート39'!$a$1),"",IF(OR(表紙!$D$4="",'試作シート39'!$d$4="",'試作シート39'!$b$5="",'試作シート39'!$d$5=""),"(入力待ち)",表紙!$D$4&"_"&'試作シート39'!$d$4&"_"&TEXT('試作シート39'!$b$5,"yyyymmdd")&TEXT('試作シート39'!$d$5,"hhmm")&"_"&A40)) | D40: =IFERROR(IF('試作シート39'!b2="","",'試作シート39'!b2),"") | E40: =IFERROR(IF('試作シート39'!b3="","",'試作シート39'!b3),"") | F40: =IFERROR(IF('試作シート39'!b4="","",'試作シート39'!b4),"") | G40: =IFERROR(IF('試作シート39'!d4="","",'試作シート39'!d4),"") | H40: =IFERROR(IF('試作シート39'!b5="","",'試作シート39'!b5),"") | I40: =IFERROR(IF('試作シート39'!d5="","",'試作シート39'!d5),"") | J40: =IFERROR(IF('試作シート39'!b6="","",'試作シート39'!b6),"") | K40: =IFERROR(IF('試作シート39'!d6="","",'試作シート39'!d6),"") | L40: =IFERROR(IF('試作シート39'!b7="","",'試作シート39'!b7),"") | M40: =IFERROR(IF('試作シート39'!b8="","",'試作シート39'!b8),"") | N40: =IFERROR(IF('試作シート39'!b9="","",'試作シート39'!b9),"")
...
